<?xml version="1.0" encoding="UTF-8"?>
<testng-results ignored="0" total="2" passed="0" failed="2" skipped="0">
  <reporter-output>
  </reporter-output>
  <suite started-at="2020-04-27T15:58:16Z" name="Suite" finished-at="2020-04-27T15:58:16Z" duration-ms="64">
    <groups>
    </groups>
    <test started-at="2020-04-27T15:58:16Z" name="Test" finished-at="2020-04-27T15:58:16Z" duration-ms="64">
      <class name="com.selenium.testng.SoftvsHardErrorTest">
        <test-method is-config="true" signature="beforeClass()[pri:0, instance:com.selenium.testng.SoftvsHardErrorTest@7d20d0b]" started-at="2020-04-27T21:28:16Z" name="beforeClass" finished-at="2020-04-27T21:28:16Z" duration-ms="11" status="PASS">
          <reporter-output>
          </reporter-output>
        </test-method> <!-- beforeClass -->
        <test-method signature="hardError()[pri:0, instance:com.selenium.testng.SoftvsHardErrorTest@7d20d0b]" started-at="2020-04-27T21:28:16Z" name="hardError" finished-at="2020-04-27T21:28:16Z" duration-ms="2" status="FAIL">
          <exception class="java.lang.AssertionError">
            <message>
              <![CDATA[expected [true] but found [false]]]>
            </message>
            <full-stacktrace>
              <![CDATA[java.lang.AssertionError: expected [true] but found [false]
	at org.testng.Assert.fail(Assert.java:94)
	at org.testng.Assert.failNotEquals(Assert.java:513)
	at org.testng.Assert.assertTrue(Assert.java:42)
	at org.testng.Assert.assertTrue(Assert.java:52)
	at com.selenium.testng.SoftvsHardErrorTest.hardError(SoftvsHardErrorTest.java:17)
	at java.base/jdk.internal.reflect.NativeMethodAccessorImpl.invoke0(Native Method)
	at java.base/jdk.internal.reflect.NativeMethodAccessorImpl.invoke(NativeMethodAccessorImpl.java:62)
	at java.base/jdk.internal.reflect.DelegatingMethodAccessorImpl.invoke(DelegatingMethodAccessorImpl.java:43)
	at java.base/java.lang.reflect.Method.invoke(Method.java:566)
	at org.testng.internal.MethodInvocationHelper.invokeMethod(MethodInvocationHelper.java:104)
	at org.testng.internal.Invoker.invokeMethod(Invoker.java:645)
	at org.testng.internal.Invoker.invokeTestMethod(Invoker.java:851)
	at org.testng.internal.Invoker.invokeTestMethods(Invoker.java:1177)
	at org.testng.internal.TestMethodWorker.invokeTestMethods(TestMethodWorker.java:129)
	at org.testng.internal.TestMethodWorker.run(TestMethodWorker.java:112)
	at org.testng.TestRunner.privateRun(TestRunner.java:756)
	at org.testng.TestRunner.run(TestRunner.java:610)
	at org.testng.SuiteRunner.runTest(SuiteRunner.java:387)
	at org.testng.SuiteRunner.runSequentially(SuiteRunner.java:382)
	at org.testng.SuiteRunner.privateRun(SuiteRunner.java:340)
	at org.testng.SuiteRunner.run(SuiteRunner.java:289)
	at org.testng.SuiteRunnerWorker.runSuite(SuiteRunnerWorker.java:52)
	at org.testng.SuiteRunnerWorker.run(SuiteRunnerWorker.java:86)
	at org.testng.TestNG.runSuitesSequentially(TestNG.java:1293)
	at org.testng.TestNG.runSuitesLocally(TestNG.java:1218)
	at org.testng.TestNG.runSuites(TestNG.java:1133)
	at org.testng.TestNG.run(TestNG.java:1104)
	at org.apache.maven.surefire.testng.TestNGExecutor.run(TestNGExecutor.java:283)
	at org.apache.maven.surefire.testng.TestNGXmlTestSuite.execute(TestNGXmlTestSuite.java:75)
	at org.apache.maven.surefire.testng.TestNGProvider.invoke(TestNGProvider.java:120)
	at org.apache.maven.surefire.booter.ForkedBooter.invokeProviderInSameClassLoader(ForkedBooter.java:384)
	at org.apache.maven.surefire.booter.ForkedBooter.runSuitesInProcess(ForkedBooter.java:345)
	at org.apache.maven.surefire.booter.ForkedBooter.execute(ForkedBooter.java:126)
	at org.apache.maven.surefire.booter.ForkedBooter.main(ForkedBooter.java:418)
]]>
            </full-stacktrace>
          </exception> <!-- java.lang.AssertionError -->
          <reporter-output>
          </reporter-output>
        </test-method> <!-- hardError -->
        <test-method signature="softError()[pri:0, instance:com.selenium.testng.SoftvsHardErrorTest@7d20d0b]" started-at="2020-04-27T21:28:16Z" name="softError" finished-at="2020-04-27T21:28:16Z" duration-ms="24" status="FAIL">
          <exception class="java.lang.AssertionError">
            <message>
              <![CDATA[The following asserts failed:
	expected [true] but found [false],
	expected [false] but found [true],
	expected [Failed] but found [Sample]]]>
            </message>
            <full-stacktrace>
              <![CDATA[java.lang.AssertionError: The following asserts failed:
	expected [true] but found [false],
	expected [false] but found [true],
	expected [Failed] but found [Sample]
	at org.testng.asserts.SoftAssert.assertAll(SoftAssert.java:43)
	at com.selenium.testng.SoftvsHardErrorTest.softError(SoftvsHardErrorTest.java:33)
	at java.base/jdk.internal.reflect.NativeMethodAccessorImpl.invoke0(Native Method)
	at java.base/jdk.internal.reflect.NativeMethodAccessorImpl.invoke(NativeMethodAccessorImpl.java:62)
	at java.base/jdk.internal.reflect.DelegatingMethodAccessorImpl.invoke(DelegatingMethodAccessorImpl.java:43)
	at java.base/java.lang.reflect.Method.invoke(Method.java:566)
	at org.testng.internal.MethodInvocationHelper.invokeMethod(MethodInvocationHelper.java:104)
	at org.testng.internal.Invoker.invokeMethod(Invoker.java:645)
	at org.testng.internal.Invoker.invokeTestMethod(Invoker.java:851)
	at org.testng.internal.Invoker.invokeTestMethods(Invoker.java:1177)
	at org.testng.internal.TestMethodWorker.invokeTestMethods(TestMethodWorker.java:129)
	at org.testng.internal.TestMethodWorker.run(TestMethodWorker.java:112)
	at org.testng.TestRunner.privateRun(TestRunner.java:756)
	at org.testng.TestRunner.run(TestRunner.java:610)
	at org.testng.SuiteRunner.runTest(SuiteRunner.java:387)
	at org.testng.SuiteRunner.runSequentially(SuiteRunner.java:382)
	at org.testng.SuiteRunner.privateRun(SuiteRunner.java:340)
	at org.testng.SuiteRunner.run(SuiteRunner.java:289)
	at org.testng.SuiteRunnerWorker.runSuite(SuiteRunnerWorker.java:52)
	at org.testng.SuiteRunnerWorker.run(SuiteRunnerWorker.java:86)
	at org.testng.TestNG.runSuitesSequentially(TestNG.java:1293)
	at org.testng.TestNG.runSuitesLocally(TestNG.java:1218)
	at org.testng.TestNG.runSuites(TestNG.java:1133)
	at org.testng.TestNG.run(TestNG.java:1104)
	at org.apache.maven.surefire.testng.TestNGExecutor.run(TestNGExecutor.java:283)
	at org.apache.maven.surefire.testng.TestNGXmlTestSuite.execute(TestNGXmlTestSuite.java:75)
	at org.apache.maven.surefire.testng.TestNGProvider.invoke(TestNGProvider.java:120)
	at org.apache.maven.surefire.booter.ForkedBooter.invokeProviderInSameClassLoader(ForkedBooter.java:384)
	at org.apache.maven.surefire.booter.ForkedBooter.runSuitesInProcess(ForkedBooter.java:345)
	at org.apache.maven.surefire.booter.ForkedBooter.execute(ForkedBooter.java:126)
	at org.apache.maven.surefire.booter.ForkedBooter.main(ForkedBooter.java:418)
]]>
            </full-stacktrace>
          </exception> <!-- java.lang.AssertionError -->
          <reporter-output>
          </reporter-output>
        </test-method> <!-- softError -->
        <test-method is-config="true" signature="afterClass()[pri:0, instance:com.selenium.testng.SoftvsHardErrorTest@7d20d0b]" started-at="2020-04-27T21:28:16Z" name="afterClass" finished-at="2020-04-27T21:28:16Z" duration-ms="0" status="PASS">
          <reporter-output>
          </reporter-output>
        </test-method> <!-- afterClass -->
      </class> <!-- com.selenium.testng.SoftvsHardErrorTest -->
    </test> <!-- Test -->
  </suite> <!-- Suite -->
</testng-results>
